<?xml version="1.0"?>
<!-- created with Phobos 0.7 -->
  <robot name="easy4_front">

    <link name="fl_knee">
      <inertial>
        <origin xyz="0 0.043966 -0.000431" rpy="0 0 0"/>
        <mass value="0.29"/>
        <inertia ixx="0.001683" ixy="0" ixz="0" iyy="7.1e-05" iyz="6e-06" izz="0.001658"/>
      </inertial>
      <visual name="Cylinder.007">
        <origin xyz="0 0 0" rpy="0 0 3.141593"/>
        <geometry>
          <cylinder radius="0.0185" length="0.05"/>
        </geometry>
        <material name="Material.002"/>
      </visual>
      <visual name="Cylinder.012">
        <origin xyz="0 0.095 -0.0025" rpy="1.570796 0 3.141593"/>
        <geometry>
          <cylinder radius="0.009802" length="0.171213"/>
        </geometry>
        <material name="Material.002"/>
      </visual>
      <visual name="Sphere.018">
        <origin xyz="0 0.2 0" rpy="1.570796 1.570796 0"/>
        <geometry>
          <sphere radius="0.025"/>
        </geometry>
      </visual>
      <collision name="Cylinder.017">
        <origin xyz="0 0.095 -0.0025" rpy="1.570796 0 3.141592"/>
        <geometry>
          <box size="0.019603 0.019603 0.171213"/>
        </geometry>
      </collision>
      <collision name="Cylinder.023">
        <origin xyz="0 0 0" rpy="0 0 3.141593"/>
        <geometry>
          <box size="0.037 0.037 0.05"/>
        </geometry>
      </collision>
      <collision name="Sphere.015">
        <origin xyz="0 0.2 0" rpy="1.570796 1.570796 0"/>
        <geometry>
          <sphere radius="0.025"/>
        </geometry>
      </collision>
    </link>

    <link name="fl_shoulder_pitch">
      <inertial>
        <origin xyz="0 0.01497 -0.0005" rpy="0 0 0"/>
        <mass value="0.25"/>
        <inertia ixx="0.000356" ixy="0" ixz="0" iyy="6.1e-05" iyz="7e-06" izz="0.000331"/>
      </inertial>
      <visual name="Cylinder.003">
        <origin xyz="0 0 0" rpy="0 0 3.141593"/>
        <geometry>
          <cylinder radius="0.0185" length="0.05"/>
        </geometry>
        <material name="Material.002"/>
      </visual>
      <visual name="Cylinder.013">
        <origin xyz="0 0.074848 -0.0025" rpy="1.570796 0 3.141593"/>
        <geometry>
          <cylinder radius="0.009802" length="0.130969"/>
        </geometry>
        <material name="Material.002"/>
      </visual>
      <collision name="Cylinder.019">
        <origin xyz="0 0.076168 -0.0025" rpy="1.570796 0 3.141593"/>
        <geometry>
          <box size="0.019603 0.019603 0.114626"/>
        </geometry>
      </collision>
      <collision name="Cylinder.021">
        <origin xyz="0 0 0" rpy="0 0 3.141593"/>
        <geometry>
          <box size="0.037 0.037 0.05"/>
        </geometry>
      </collision>
    </link>

    <link name="fl_shoulder_roll">
      <visual name="Sphere.026">
        <origin xyz="0 -0.023544 0" rpy="1.570796 1.570796 0"/>
        <geometry>
          <sphere radius="0.0125"/>
        </geometry>
        <material name="Material.002"/>
      </visual>
      <collision name="Sphere.031">
        <origin xyz="0 -0.023544 0" rpy="1.570796 1.570796 0"/>
        <geometry>
          <box size="0.025 0.025 0.025"/>
        </geometry>
      </collision>
    </link>

    <link name="fl_shoulder_yaw">
      <visual name="Sphere.025">
        <origin xyz="0 0 0.048544" rpy="0 0 -1.570796"/>
        <geometry>
          <sphere radius="0.0125"/>
        </geometry>
        <material name="Material.002"/>
      </visual>
      <collision name="Sphere.032">
        <origin xyz="0 0 0.048544" rpy="0 0 -1.570796"/>
        <geometry>
          <box size="0.025 0.025 0.025"/>
        </geometry>
      </collision>
    </link>

    <link name="fr_knee">
      <inertial>
        <origin xyz="0 0.043966 0" rpy="0 0 0"/>
        <mass value="0.29"/>
        <inertia ixx="0.001683" ixy="0" ixz="0" iyy="7.1e-05" iyz="0" izz="0.001658"/>
      </inertial>
      <visual name="Cylinder.006">
        <origin xyz="0 0 0" rpy="-3.141592 0 0"/>
        <geometry>
          <cylinder radius="0.0185" length="0.05"/>
        </geometry>
        <material name="Material.002"/>
      </visual>
      <visual name="Cylinder.009">
        <origin xyz="0 0.095 0" rpy="-1.570796 0 0"/>
        <geometry>
          <cylinder radius="0.009802" length="0.171213"/>
        </geometry>
        <material name="Material.002"/>
      </visual>
      <visual name="Sphere.016">
        <origin xyz="0 0.2 0" rpy="1.570796 -1.570796 0"/>
        <geometry>
          <sphere radius="0.025"/>
        </geometry>
      </visual>
      <collision name="Cylinder.020">
        <origin xyz="0 0.095 0" rpy="-1.570796 0 0"/>
        <geometry>
          <box size="0.019603 0.019603 0.171213"/>
        </geometry>
      </collision>
      <collision name="Cylinder.027">
        <origin xyz="0 0 0" rpy="-3.141592 0 0"/>
        <geometry>
          <box size="0.037 0.037 0.05"/>
        </geometry>
      </collision>
      <collision name="Sphere.014">
        <origin xyz="0 0.2 0" rpy="1.570796 -1.570796 0"/>
        <geometry>
          <sphere radius="0.025"/>
        </geometry>
      </collision>
    </link>

    <link name="fr_shoulder_pitch">
      <inertial>
        <origin xyz="0 0.01497 0" rpy="0 0 0"/>
        <mass value="0.25"/>
        <inertia ixx="0.000356" ixy="0" ixz="0" iyy="6.1e-05" iyz="0" izz="0.000331"/>
      </inertial>
      <visual name="Cylinder.002">
        <origin xyz="0 0 0" rpy="-3.141592 0 0"/>
        <geometry>
          <cylinder radius="0.0185" length="0.05"/>
        </geometry>
        <material name="Material.002"/>
      </visual>
      <visual name="Cylinder.008">
        <origin xyz="0 0.074848 0" rpy="-1.570796 0 0"/>
        <geometry>
          <cylinder radius="0.009802" length="0.130969"/>
        </geometry>
        <material name="Material.002"/>
      </visual>
      <collision name="Cylinder.022">
        <origin xyz="0 0.076168 0" rpy="-1.570796 0 0"/>
        <geometry>
          <box size="0.019603 0.019603 0.114626"/>
        </geometry>
      </collision>
      <collision name="Cylinder.026">
        <origin xyz="0 0 0" rpy="-3.141592 0 0"/>
        <geometry>
          <box size="0.037 0.037 0.05"/>
        </geometry>
      </collision>
    </link>

    <link name="fr_shoulder_roll">
      <visual name="Sphere.023">
        <origin xyz="0 -0.023544 0" rpy="1.570796 1.570796 0"/>
        <geometry>
          <sphere radius="0.0125"/>
        </geometry>
        <material name="Material.002"/>
      </visual>
      <collision name="Sphere.033">
        <origin xyz="0 -0.023544 0" rpy="1.570796 1.570796 0"/>
        <geometry>
          <box size="0.025 0.025 0.025"/>
        </geometry>
      </collision>
    </link>

    <link name="fr_shoulder_yaw">
      <visual name="Sphere.024">
        <origin xyz="0 0 0.048544" rpy="0 0 -1.570796"/>
        <geometry>
          <sphere radius="0.0125"/>
        </geometry>
        <material name="Material.002"/>
      </visual>
      <collision name="Sphere.034">
        <origin xyz="0 0 0.048544" rpy="0 0 -1.570796"/>
        <geometry>
          <box size="0.025 0.025 0.025"/>
        </geometry>
      </collision>
    </link>

    <link name="root">
      <inertial>
        <origin xyz="0 0 0" rpy="0 0 0"/>
        <mass value="2.5"/>
        <inertia ixx="0.017097" ixy="0" ixz="0" iyy="0.050151" iyz="0" izz="0.064909"/>
      </inertial>
      <visual name="Cube.005">
        <origin xyz="-0.15 0 0" rpy="0 0 1.570796"/>
        <geometry>
          <box size="0.3 0.15 0.075"/>
        </geometry>
        <material name="Material.001"/>
      </visual>
      <visual name="Sphere.020">
        <origin xyz="-0.218381 0 0.060072" rpy="0 0 0"/>
        <geometry>
          <sphere radius="0.024453"/>
        </geometry>
        <material name="Material.002"/>
      </visual>
      <collision name="Cube.001">
        <origin xyz="-0.15 0 0" rpy="0 0 1.570796"/>
        <geometry>
          <box size="0.3 0.15 0.075"/>
        </geometry>
      </collision>
    </link>

    <joint name="fl_knee" type="revolute">
      <origin xyz="0 0.15 0" rpy="0 0 0"/>
      <parent link="fl_shoulder_pitch"/>
      <child link="fl_knee"/>
      <axis xyz="0 0 1.0"/>
      <limit lower="-3.141593" upper="3.141593" effort="2.0" velocity="1.047198"/>
    </joint>

    <joint name="fl_shoulder_pitch" type="revolute">
      <origin xyz="0 0 0" rpy="0 -1.570796 0"/>
      <parent link="fl_shoulder_roll"/>
      <child link="fl_shoulder_pitch"/>
      <axis xyz="0 0 1.0"/>
      <limit lower="-3.141593" upper="3.141593" effort="2.0" velocity="1.047198"/>
    </joint>

    <joint name="fl_shoulder_roll" type="revolute">
      <origin xyz="0 0 0" rpy="-1.570796 0 0"/>
      <parent link="fl_shoulder_yaw"/>
      <child link="fl_shoulder_roll"/>
      <axis xyz="0 0 1.0"/>
      <limit lower="-3.141593" upper="3.141593" effort="2.0" velocity="1.047198"/>
    </joint>

    <joint name="fl_shoulder_yaw" type="revolute">
      <origin xyz="-0.2 -0.175 0" rpy="0 0 1.570796"/>
      <parent link="root"/>
      <child link="fl_shoulder_yaw"/>
      <axis xyz="0 0 1.0"/>
      <limit lower="-3.141593" upper="3.141593" effort="2.0" velocity="1.047198"/>
    </joint>

    <joint name="fr_knee" type="revolute">
      <origin xyz="0 0.15 0" rpy="0 0 0"/>
      <parent link="fr_shoulder_pitch"/>
      <child link="fr_knee"/>
      <axis xyz="0 0 1.0"/>
      <limit lower="-3.141593" upper="3.141593" effort="2.0" velocity="1.047198"/>
    </joint>

    <joint name="fr_shoulder_pitch" type="revolute">
      <origin xyz="0 0 0" rpy="0 1.570796 0"/>
      <parent link="fr_shoulder_roll"/>
      <child link="fr_shoulder_pitch"/>
      <axis xyz="0 0 1.0"/>
      <limit lower="-3.141593" upper="3.141593" effort="2.0" velocity="1.047198"/>
    </joint>

    <joint name="fr_shoulder_roll" type="revolute">
      <origin xyz="0 0 0" rpy="-1.570796 0 0"/>
      <parent link="fr_shoulder_yaw"/>
      <child link="fr_shoulder_roll"/>
      <axis xyz="0 0 1.0"/>
      <limit lower="-3.141593" upper="3.141593" effort="2.0" velocity="1.047198"/>
    </joint>

    <joint name="fr_shoulder_yaw" type="revolute">
      <origin xyz="-0.2 0.175 0" rpy="0 0 1.570796"/>
      <parent link="root"/>
      <child link="fr_shoulder_yaw"/>
      <axis xyz="0 0 1.0"/>
      <limit lower="-3.141593" upper="3.141593" effort="2.0" velocity="1.047198"/>
    </joint>

    <material name="Material.001">
      <color rgba="0.19181 0.326071 0.64 1.0"/>
    </material>

    <material name="Material.002">
      <color rgba="0.64 0.486493 0.244805 1.0"/>
    </material>

  </robot>
